<?xml version="1.0"?>
<robot name="plane_with_payload">

  <link name="plane">
    <visual>
      <geometry>
        <box size="1 1 0.2"/>
      </geometry>
      <material name="blue"/>
    </visual>
    <collision>
      <geometry>
        <box size="1 1 0.2"/>
      </geometry>
    </collision>
  </link>

  <link name="payload">
    <visual>
      <geometry>
        <sphere radius="0.1"/>
      </geometry>
      <material name="red"/>
    </visual>
    <collision>
      <geometry>
        <sphere radius="0.1"/>
      </geometry>
    </collision>
  </link>

  <joint name="plane_payload_joint" type="revolute">
    <parent link="plane"/>
    <child link="payload"/>
    <origin xyz="0 0 -0.3"/>
  </joint>

</robot>

